<?xml version="1.0"?>
<robot name="robot1">
  <link name="base_link">
    <visual>
      <geometry>
        <mesh  scale="0.025 0.025 0.025" filename="package://R1_urdf/bot_body.dae"/>
      </geometry>
      <origin xyz="0 0 0.226"/>
    </visual>
  </link>

  <link name="kinect_rgb">
    <visual>
      <origin rpy="0 0 0" xyz="0 0 0"/>
      <geometry>
        <mesh  scale="0.025 0.025 0.025" filename="package://R1_urdf/bot_kinect.dae"/>
      </geometry>
      <origin rpy="0 0 0" xyz="0 0 0"/>
    </visual>
  </link>

  <link name="wheel_1">
    <visual>
      <origin rpy="0 0 0" xyz="0 0 0"/>
      <geometry>
        <mesh  scale="0.025 0.025 0.025" filename="package://R1_urdf/bot_wheel.dae"/>
      </geometry>
    </visual>
  </link>

  <link name="wheel_2">
    <visual>
      <origin rpy="0 0 0" xyz="0 0 0"/>
      <geometry>
        <mesh  scale="0.025 0.025 0.025" filename="package://R1_urdf/bot_wheel.dae"/>
      </geometry>
    </visual>
  </link>

  <link name="wheel_3">
    <visual>
      <origin rpy="0 0 0" xyz="0 0 0"/>
      <geometry>
        <mesh  scale="0.025 0.025 0.025" filename="package://R1_urdf/bot_wheel.dae"/>
      </geometry>
    </visual>
  </link>

  <link name="wheel_4">
    <visual>
      <origin rpy="0 0 0" xyz="0 0 0"/>
      <geometry>
        <mesh  scale="0.025 0.025 0.025" filename="package://R1_urdf/bot_wheel.dae"/>
      </geometry>
    </visual>
  </link>

  <link name="PLS200">
    <visual>
      <origin rpy="0 0 0" xyz="0 0 0"/>
      <geometry>
        <mesh  scale="0.025 0.025 0.025" filename="package://R1_urdf/bot_PLS200.dae"/>
      </geometry>
    </visual>
  </link>

  <joint name="join_1" type="continuous">
    <parent link="base_link"/>
    <child link="wheel_1"/>
    <axis xyz="0 0 1"/>
    <origin rpy="0 0 0" xyz="0.235 -0.17 0"/>
  </joint>

  <joint name="join_2" type="continuous">
    <parent link="base_link"/>
    <child link="wheel_2"/>
    <axis xyz="0 0 1"/>
    <origin rpy="0 0 3.14" xyz="0.235 0.17 0"/>
  </joint>

  <joint name="join_3" type="continuous">
    <parent link="base_link"/>
    <child link="wheel_3"/>
    <axis xyz="0 0 1"/>
    <origin rpy="0 0 0 " xyz="-0.235 -0.17 0"/>
  </joint>

  <joint name="join_4" type="continuous">
    <parent link="base_link"/>
    <child link="wheel_4"/>
    <axis xyz="0 0 1"/>
    <origin rpy="0 0 3.14" xyz="-0.235 0.17 0"/>
  </joint>

  <joint name="join_5" type="continuous">
    <parent link="base_link"/>
    <child link="kinect_rgb"/>
    <origin rpy="-1.57 0 -1.570" xyz="0.320 0 0.555"/>    
  </joint>

  <joint name="join_6" type="continuous">
    <parent link="base_link"/>
    <child link="PLS200"/>
    <origin rpy="0 0 0" xyz="0.420 0 0.26"/>
  </joint>

</robot>


